O bloco `try...catch` em **JavaScript** √© usado para capturar e tratar **erros** que possam ocorrer durante a execu√ß√£o do c√≥digo, evitando que o programa quebre completamente.

```
try {
  let resultado = 10 / 0;  // N√£o gera erro, mas retorna Infinity
  console.log(naoExiste);  // Vai gerar um erro (vari√°vel n√£o definida)
} catch (erro) {
  console.log("Ocorreu um erro:", erro.message);
}

```

## üîπ **Lan√ßando Erros com `throw`**

Podemos criar nossos pr√≥prios erros usando `throw`.
```
function dividir(a, b) {
  if (b === 0) {
    throw new Error("Divis√£o por zero n√£o √© permitida!");
  }
  return a / b;
}

try {
  console.log(dividir(10, 0)); // Isso gerar√° um erro
} catch (erro) {
  console.log("Erro:", erro.message);
}

```



## üîπ **Quando Usar `try...catch`?**

‚úî Para capturar erros **imprevis√≠veis**  
‚úî Para evitar que o c√≥digo **pare de funcionar**  
‚úî Para tratar **requisi√ß√µes ass√≠ncronas** (`fetch`, `async/await`)


## üîπ **Tratando Erros em Fun√ß√µes Ass√≠ncronas**

Se estiver usando `async/await`, envolva a chamada dentro de `try...catch`.
async function buscarDados() {
  try {
    let resposta = await fetch("https://jsonplaceholder.typicode.com/users");
    let dados = await resposta.json();
    console.log(dados);
  } catch (erro) {
    console.log("Erro na requisi√ß√£o:", erro.message);
  }
}

buscarDados();
